Workbook
Name SCENARIO_ACTIF: '00_CONFIG__T_PARAMETRES'!$H$2

Sheet DIM_FAM_METIER
A1: FAM_METIER_ID | B1: CODE_FAM_METIER | C1: LIBELLE_FAM_METIER | D1: CATEGORIE_METIER | E1: ORDRE_AFFICHAGE
A2: FM_01 | B2: STRUCTURE | C2: Structure & Gros Œuvre | D2: STRUCTURE | E2: 1
A3: FM_02 | B3: ENVELOPPE | C3: Enveloppe & Étanchéité | D3: FINITION | E3: 2
A4: FM_03 | B4: FINITION | C4: Menuiserie & Finitions | D4: FINITION | E4: 3
A5: FM_04 | B5: TECHNIQUE | C5: Corps Techniques | D5: TECHNIQUE | E5: 4

Sheet 00_ARCHITECTURE
A1: 🏗️ ARCHITECTURE OFFICIELLE — MOTEUR DÉCISIONNEL CHANTIER V2.0
B3: ⚙️ COUCHE CONFIG
B4: → 00_CONFIG__T_PARAMETRES_ACTIVE
B5: → 00_CONFIG__T_PARAMETRES (scénarios)
B6: → T_PROJET
C7: ℹ️ Pilote tout le moteur — paramètres dynamiques — simulation scénarios
B9: 📐 COUCHE DIMENSIONS
B10: → DIM_FAM_METIER
B11: → DIM_FAM_ARTICLE (17 familles)
B12: → DIM_LOT (17 lots)
C13: ℹ️ Tables stables — modèle étoile Power BI — référentiels analytiques
B15: 📥 COUCHE RAW — Données Brutes
B16: → 01_RAW__METRE (318 articles)
B17: → 01_RAW__BPU_LOCAL
B18: → 01_RAW__BPU_CHINE
C19: ℹ️ Source immuable — jamais modifiée — traçabilité garantie
B21: 🧹 COUCHE CLEAN — Données Nettoyées
B22: → 02_CLEAN__T_METRE
B23: → 02_CLEAN__BPU_LOCAL
B24: → 02_CLEAN__BPU_CHINE
C25: ℹ️ Harmonisation unités — suppression erreurs — normalisation texte
B27: ⚡ COUCHE STAGING — Cœur Décisionnel
B28: → 03_STAGING__METRE_ENRICHI
B29: → → PU_LOCAL + PU_IMPORT_NET
B30: → → TAUX_ECONOMIE + DECISION_IMPORT
C31: ℹ️ Jointures + calculs — 163 IMPORT | 142 LOCAL | 13 ARBITRAGE
B33: 📊 COUCHE FACT — Table Consolidée
B34: → 04_FACT_METRE (318 lignes)
C35: ℹ️ Table économique finale — base de toutes les agrégations
B37: 🗄️ COUCHE DATAMART — Agrégations
B38: → 05_DM_LOT (17 lots)
B39: → 05_DM_FAM_ARTICLE (17 familles)
B40: → 05_DM_PROJET (KPIs globaux)
C41: ℹ️ Optimisé Power BI — granularités LOT / FAM / PROJET
B43: 🧠 COUCHE ANALYTICS — Intelligence
B44: → 06_ANALYTICS__SCORE_STRATEGIQUE
B45: → 07_INTELLIGENCE__DECISION
B46: → 09_DM_MATRICE_GAIN_RISQUE
C47: ℹ️ Scores multicritères — IPI — quadrant stratégique — classe A/B/C
B49: 📋 COUCHE DASHBOARD — Direction
...

Sheet ---01_CONFIGURATION ---

Sheet PARAM_GLOBAL
A1: PARAM | B1: VALUE | C1: TYPE
A2: Mode_Sourcing | B2: Mixte | C2: GENERAL
A3: Devise_Modele | B3: FCFA | C3: GENERAL
A4: COUT_CONTAINER | B4: 2500000 | C4: LOGISTIQUE
A5: CAPACITE_CONTAINER | B5: 28 | C5: LOGISTIQUE
A6: SEUIL_DECISION_IMPORT | B6: 0.05 | C6: DECISION
A7: POIDS_PRIX | B7: 0.4 | C7: DECISION
A8: POIDS_RISQUE | B8: 0.3 | C8: DECISION
A9: POIDS_DELAI | B9: 0.2 | C9: DECISION
A10: POIDS_VOLUME | B10: 0.1 | C10: DECISION
A11: TAUX_MARGE_LOCAL | B11: 0.15 | C11: FINANCE
A12: TAUX_MARGE_IMPORT | B12: 0.08 | C12: FINANCE
A13: TAUX_TRANSPORT_MARITIME | B13: 0.12 | C13: LOGISTIQUE
A14: TAUX_ASSURANCE | B14: 0.005 | C14: LOGISTIQUE
A15: TAUX_DOUANE | B15: 0.18 | C15: LOGISTIQUE
... A20: TAUX_CHANGE_USD | B20: 600 | C20: FINANCE

Sheet T_PARAM_IMPORT
A1: PROJET_ID | B1: TRANSPORT | C1: ASSURANCE | D1: DOUANE | E1: PORT | F1: LOGISTIQUE | G1: TRANSPORT_LOCAL | H1: CHANGE | I1: MARGE | J1: IMPREVUS | K1: TAUX_TRANSPORT_MARITIME | L1: TAUX_ASSURANCE | M1: TAUX_DOUANE | N1: TAUX_FRAIS_PORT | O1: TAUX_LOGISTIQUE | P1: TAUX_TRANSPORT_LOCAL | Q1: TAUX_CHANGE_USD | R1: TAUX_MARGE_IMPORT | S1: TAUX_IMPREVUS_IMPORT
A2: PNR_MEDICAL_CENTER | B2: 0.12 | C2: 0.005 | D2: 0.18 | E2: 0.04 | F2: 0.03 | G2: 0.05 | H2: 600 | I2: 0.08 | J2: 0.03 | K2: 0.12 | L2: 0.005 | M2: 0.18 | N2: 0.04 | O2: 0.03 | P2: 0.05 | Q2: 600 | R2: 0.08 | S2: 0.03

Sheet 00_POWER_QUERY
B1: ⚡ MOTEUR POWER QUERY M — Centre Médical Pointe Noire
B2: Version | C2: 2.0 — Formules dynamiques · Scénarios OPTIMISTE / RÉALISTE / STRESS · 318 articles · 17 lots
B3: Architecture | C3: CONFIG → DIMENSIONS → RAW → CLEAN → STAGING → FACT → DATAMART → ANALYTICS
B4: Clé de jointure | C4: CODE_BPU — relie METRE ↔ BPU_LOCAL ↔ BPU_CHINE (ex : "2.1", "7.A.3")
B5: Levier scénario | C5: Changer H2 dans T_PARAMETRES → tous les calculs STAGING se mettent à jour
B7: 📐 ARCHITECTURE DU FLUX DE DONNÉES
B8: 00_CONFIG | C8: T_PARAMETRES → H2 = scénario actif → T_PARAMETRES_ACTIVE → STAGING
B9: DIMENSIONS | C9: DIM_LOT / DIM_FAM_* → Tables de référence stables — enrichissent STAGING
B10: 01_RAW | C10: METRE / BPU_LOCAL / BPU_CHINE → Sources brutes immuables — ne jamais modifier
B11: 02_CLEAN | C11: CLEAN_METRE / CLEAN_BPU_LOCAL / CLEAN_BPU_CHINE → Nettoyage + contrôle qualité
B12: 03_STAGING | C12: METRE_ENRICHI → ★ CŒUR — Jointures + calculs économiques dynamiques
B13: 04_FACT | C13: FACT_METRE → Table de faits finale — 318 lignes × 14 colonnes
B14: 05_DM | C14: DM_LOT / DM_FAM / DM_PROJET → Agrégations par lot, famille, projet
B15: 06-07 ANALYTICS | C15: SCORE + INTELLIGENCE → Scoring multicritères + matrice décisionnelle
B16: 08-10 DASH | C16: KPI + MATRICE + DASHBOARD → Synthèse exécutive
B18: ═══ COUCHE 0 — CONNEXION SOURCE ═══
B20: Source_ExcelFichier — Connexion centralisée au classeur
B21: 🎯 Rôle : Point d'entrée unique vers BE_MONOPROJET_V2_PNMC.xlsx. Toutes les requêtes référencent Source_ExcelFichier — changer le chemin ici suffit pour pointer vers un autre fichier.
B22: 🏷 CONNEXION · PARAMÈTRE · SOURCE
B23: // Source_ExcelFichier.pq | Power Query M Language
B24: // ─────────────────────────────────────────────────────────────────────────
B25: // CONNEXION CENTRALISÉE AU FICHIER EXCEL SOURCE
B26: // Modifier UNIQUEMENT ici pour changer le chemin du fichier.
B27: // ─────────────────────────────────────────────────────────────────────────
B28: let
B29: // ⚠️ ADAPTER CE CHEMIN À VOTRE ENVIRONNEMENT :
B30: // • Local Windows : "C:\\Projets\\PNMC\\BE_MONOPROJET_V2_PNMC.xlsx"
... B36: // delayTypes = true → ne pas inférer les types tout de suite (+ rapide)
B37: Source = Excel.Workbook( | C37: // ← Point de départ de TOUTES les requêtes
B38: File.Contents(CheminFichier),
B39: true, // useHeaders
B40: true // delayTypes
B41: )
B42: in
B43: Source
B45: ═══ COUCHE 00_CONFIG — SCÉNARIOS & PARAMÈTRES ═══
B47: T_PARAMETRES — Table des 3 scénarios — OPTIMISTE / RÉALISTE / STRESS
B48: 🎯 Rôle : Lit les 14 paramètres projet (marges, taux transport/douane, seuil décision, poids multicritères) sous forme de 3 colonnes scénarios. Source de vérité de TOUT le modèle financier.
B49: 🏷 CONFIG · SCÉNARIOS · PARAMÈTRES · SOURCE_VÉRITÉ
B50: // T_PARAMETRES.pq | Power Query M Language
...

Sheet CONFIG__MOTEUR_FORMULES
A1: 📐 DOCUMENTATION DES FORMULES DYNAMIQUES — MOTEUR DÉCISIONNEL PNMC
A2: SÉLECTEUR SCÉNARIO
A3: Cellule | B3: Valeur | C3: Effet sur le modèle
A4: T_PARAMETRES!H2 | B4: OPTIMISTE / RÉALISTE / STRESS | C4: Change tous les paramètres actifs en cascade
A6: FORMULES PARAMÈTRES ACTIFS
A7: Paramètre | B7: Formule dans T_PARAMETRES_ACTIVE | C7: Description
A8: Taux_Marge_Local | B8: INDEX('00_CONFIG__T_PARAMETRES'!C6:E6, 1, MATCH('00_CONFIG__T_PARAMETRES'!H2, 'T_PARAMETRES'!C2:E2, 0)) | C8: Lit la colonne scénario correspondante
A9: Taux_Marge_Chine | B9: INDEX('00_CONFIG__T_PARAMETRES'!C7:E7, 1, MATCH(...)) | C9: idem
A10: Taux_Transport | B10: INDEX('00_CONFIG__T_PARAMETRES'!C8:E8, 1, MATCH(...)) | C10: idem
A11: Taux_Douane | B11: INDEX('00_CONFIG__T_PARAMETRES'!C9:E9, 1, MATCH(...)) | C11: idem
A12: Seuil_Decision_Import | B12: INDEX('00_CONFIG__T_PARAMETRES'!C12:E12, 1, MATCH(...)) | C12: idem
A14: FORMULES STAGING
A15: Colonne | B15: Formule type | C15: Description
A16: M — PU_CHINE_FOB | B16: 0 | C16: Prix FOB source Chine (fallback = PU_LOCAL si non trouvé)
A17: N — PU_IMPORT_NET | B17: M4 * (1 + T_TRANSPORT + T_DOUANE) * (1 + T_MARGE_CHINE) | C17: Prix de revient import avec tous les coûts logistiques et marge
A18: O — PU_LOCAL_MARGE | B18: L4 * (1 + T_MARGE_LOCAL) | C18: Prix local avec marge entreprise appliquée
A19: P — MONTANT_LOCAL | B19: =J4*O4 -> 0 | C19: Montant total si exécution 100% locale
A20: Q — MONTANT_IMPORT | B20: =J4*N4 -> 0 | C20: Montant total si sourcing Chine
A21: R — ÉCONOMIE_NETTE | B21: =P4-Q4 -> 0 | C21: Gain financier net par article
A22: S — TAUX_ÉCONOMIE | B22: =IF(P4=0,0,R4/P4) -> 0 | C22: Taux de réduction CAPEX par article
A23: V — DECISION | B23: =IF(T4=0,"LOCAL",IF(S4>seuil,"IMPORT","ARBITRAGE")) -> LOCAL | C23: Décision finale — pilotée par le seuil paramétrable
A25: IMPACT DU CHANGEMENT DE SCÉNARIO
A26: Paramètre | B26: OPTIMISTE | C26: RÉALISTE | D26: STRESS | E26: Δ Impact
A27: Taux_Transport | B27: 6% | C27: 8% | D27: 12% | E27: ↑ coût import → moins de IMPORT
A28: Taux_Douane | B28: 12% | C28: 15% | D28: 20% | E28: ↑ coût import → moins de IMPORT
A29: Taux_Marge_Chine | B29: 8% | C29: 10% | D29: 15% | E29: ↑ PU_IMPORT_NET → taux éco baisse
A30: Taux_Marge_Local | B30: 12% | C30: 15% | D30: 20% | E30: ↑ PU_LOCAL_MARGE → taux éco monte
A31: Seuil_Decision_Import | B31: 3% | C31: 5% | D31: 8% | E31: ↑ seuil → moins de IMPORT décidés

Sheet 00_CONFIG__T_PARAMETRES_ACTIVE
A1: ⚙️ PARAMÈTRES ACTIFS — Pilotés par le scénario sélectionné
A2: =CONCATENATE("📊 Scénario actif : ", '00_CONFIG__T_PARAMETRES'!$H$2) -> 📊 Scénario actif : REALISTE
A3: PARAMETRE | B3: VALEUR ACTIVE | C3: OPTIMISTE | D3: RÉALISTE | E3: STRESS
A4: Nom_Projet | B4: =INDEX('00_CONFIG__T_PARAMETRES'!$C$3:$E$3,1,MATCH('00_CONFIG__T_PARAMETRES'!$H$2,'00_CONFIG__T_PARAMETRES'!$C$2:$E$2,0)) -> PNMC | C4: ='00_CONFIG__T_PARAMETRES'!$C$3 -> PNMC | D4: ='00_CONFIG__T_PARAMETRES'!$D$3 -> PNMC | E4: ='00_CONFIG__T_PARAMETRES'!$E$3 -> PNMC
A5: Mode_Sourcing | B5: =INDEX('00_CONFIG__T_PARAMETRES'!$C$4:$E$4,1,MATCH('00_CONFIG__T_PARAMETRES'!$H$2,'00_CONFIG__T_PARAMETRES'!$C$2:$E$2,0)) -> Mixte | C5: ='00_CONFIG__T_PARAMETRES'!$C$4 -> Mixte | D5: ='00_CONFIG__T_PARAMETRES'!$D$4 -> Mixte | E5: ='00_CONFIG__T_PARAMETRES'!$E$4 -> Local
A6: Devise_Modele | B6: =INDEX('00_CONFIG__T_PARAMETRES'!$C$5:$E$5,1,MATCH('00_CONFIG__T_PARAMETRES'!$H$2,'00_CONFIG__T_PARAMETRES'!$C$2:$E$2,0)) -> FCFA | C6: ='00_CONFIG__T_PARAMETRES'!$C$5 -> FCFA | D6: ='00_CONFIG__T_PARAMETRES'!$D$5 -> FCFA | E6: ='00_CONFIG__T_PARAMETRES'!$E$5 -> FCFA
A7: Taux_Marge_Local | B7: =INDEX('00_CONFIG__T_PARAMETRES'!$C$6:$E$6,1,MATCH('00_CONFIG__T_PARAMETRES'!$H$2,'00_CONFIG__T_PARAMETRES'!$C$2:$E$2,0)) -> 0.15 | C7: ='00_CONFIG__T_PARAMETRES'!$C$6 -> 0.12 | D7: ='00_CONFIG__T_PARAMETRES'!$D$6 -> 0.15 | E7: ='00_CONFIG__T_PARAMETRES'!$E$6 -> 0.2
A8: Taux_Marge_Chine | B8: =INDEX('00_CONFIG__T_PARAMETRES'!$C$7:$E$7,1,MATCH('00_CONFIG__T_PARAMETRES'!$H$2,'00_CONFIG__T_PARAMETRES'!$C$2:$E$2,0)) -> 0.1 | C8: ='00_CONFIG__T_PARAMETRES'!$C$7 -> 0.08 | D8: ='00_CONFIG__T_PARAMETRES'!$D$7 -> 0.1 | E8: ='00_CONFIG__T_PARAMETRES'!$E$7 -> 0.15
A9: Taux_Transport | B9: =INDEX('00_CONFIG__T_PARAMETRES'!$C$8:$E$8,1,MATCH('00_CONFIG__T_PARAMETRES'!$H$2,'00_CONFIG__T_PARAMETRES'!$C$2:$E$2,0)) -> 0.08 | C9: ='00_CONFIG__T_PARAMETRES'!$C$8 -> 0.06 | D9: ='00_CONFIG__T_PARAMETRES'!$D$8 -> 0.08 | E9: ='00_CONFIG__T_PARAMETRES'!$E$8 -> 0.12
A10: Taux_Douane | B10: =INDEX('00_CONFIG__T_PARAMETRES'!$C$9:$E$9,1,MATCH('00_CONFIG__T_PARAMETRES'!$H$2,'00_CONFIG__T_PARAMETRES'!$C$2:$E$2,0)) -> 0.15 | C10: ='00_CONFIG__T_PARAMETRES'!$C$9 -> 0.12 | D10: ='00_CONFIG__T_PARAMETRES'!$D$9 -> 0.15 | E10: ='00_CONFIG__T_PARAMETRES'!$E$9 -> 0.2
A11: Cout_Container | B11: =INDEX('00_CONFIG__T_PARAMETRES'!$C$10:$E$10,1,MATCH('00_CONFIG__T_PARAMETRES'!$H$2,'00_CONFIG__T_PARAMETRES'!$C$2:$E$2,0)) -> 2500000 | C11: ='00_CONFIG__T_PARAMETRES'!$C$10 -> 2200000 | D11: ='00_CONFIG__T_PARAMETRES'!$D$10 -> 2500000 | E11: ='00_CONFIG__T_PARAMETRES'!$E$10 -> 3000000
A12: Capacite_Container | B12: =INDEX('00_CONFIG__T_PARAMETRES'!$C$11:$E$11,1,MATCH('00_CONFIG__T_PARAMETRES'!$H$2,'00_CONFIG__T_PARAMETRES'!$C$2:$E$2,0)) -> 28 | C12: ='00_CONFIG__T_PARAMETRES'!$C$11 -> 30 | D12: ='00_CONFIG__T_PARAMETRES'!$D$11 -> 28 | E12: ='00_CONFIG__T_PARAMETRES'!$E$11 -> 25
A13: Seuil_Decision_Import | B13: =INDEX('00_CONFIG__T_PARAMETRES'!$C$12:$E$12,1,MATCH('00_CONFIG__T_PARAMETRES'!$H$2,'00_CONFIG__T_PARAMETRES'!$C$2:$E$2,0)) -> 0.05 | C13: ='00_CONFIG__T_PARAMETRES'!$C$12 -> 0.03 | D13: ='00_CONFIG__T_PARAMETRES'!$D$12 -> 0.05 | E13: ='00_CONFIG__T_PARAMETRES'!$E$12 -> 0.08
A14: Poids_Prix | B14: =INDEX('00_CONFIG__T_PARAMETRES'!$C$13:$E$13,1,MATCH('00_CONFIG__T_PARAMETRES'!$H$2,'00_CONFIG__T_PARAMETRES'!$C$2:$E$2,0)) -> 0.4 | C14: ='00_CONFIG__T_PARAMETRES'!$C$13 -> 0.45 | D14: ='00_CONFIG__T_PARAMETRES'!$D$13 -> 0.4 | E14: ='00_CONFIG__T_PARAMETRES'!$E$13 -> 0.35
A15: Poids_Risque | B15: =INDEX('00_CONFIG__T_PARAMETRES'!$C$14:$E$14,1,MATCH('00_CONFIG__T_PARAMETRES'!$H$2,'00_CONFIG__T_PARAMETRES'!$C$2:$E$2,0)) -> 0.3 | C15: ='00_CONFIG__T_PARAMETRES'!$C$14 -> 0.25 | D15: ='00_CONFIG__T_PARAMETRES'!$D$14 -> 0.3 | E15: ='00_CONFIG__T_PARAMETRES'!$E$14 -> 0.35
A16: Poids_Delai | B16: =INDEX('00_CONFIG__T_PARAMETRES'!$C$15:$E$15,1,MATCH('00_CONFIG__T_PARAMETRES'!$H$2,'00_CONFIG__T_PARAMETRES'!$C$2:$E$2,0)) -> 0.2 | C16: ='00_CONFIG__T_PARAMETRES'!$C$15 -> 0.2 | D16: ='00_CONFIG__T_PARAMETRES'!$D$15 -> 0.2 | E16: ='00_CONFIG__T_PARAMETRES'!$E$15 -> 0.2
A17: Poids_Volume | B17: =INDEX('00_CONFIG__T_PARAMETRES'!$C$16:$E$16,1,MATCH('00_CONFIG__T_PARAMETRES'!$H$2,'00_CONFIG__T_PARAMETRES'!$C$2:$E$2,0)) -> 0.1 | C17: ='00_CONFIG__T_PARAMETRES'!$C$16 -> 0.1 | D17: ='00_CONFIG__T_PARAMETRES'!$D$16 -> 0.1 | E17: ='00_CONFIG__T_PARAMETRES'!$E$16 -> 0.1

Sheet 00_CONFIG__T_PARAMETRES
A1: ⚙️ PARAMÈTRES PROJET — SCÉNARIOS OPTIMISTE / RÉALISTE / STRESS | B1: Colonne1 | C1: Colonne2 | D1: Colonne3 | E1: Colonne4 | F1: Colonne5 | H1: 🎯 SCENARIO ACTIF
A2: CATEGORIE | B2: PARAMETRE | C2: OPTIMISTE | D2: REALISTE | E2: STRESS | F2: DESCRIPTION | H2: REALISTE
A3: GENERAL | B3: Nom_Projet | C3: PNMC | D3: PNMC | E3: PNMC | F3: Nom officiel du projet | H3: ↑ Modifier ici : OPTIMISTE / RÉALISTE / STRESS
A4: GENERAL | B4: Mode_Sourcing | C4: Mixte | D4: Mixte | E4: Local | F4: Stratégie approvisionnement
A5: GENERAL | B5: Devise_Modele | C5: FCFA | D5: FCFA | E5: FCFA | F5: Devise de référence
A6: FINANCE | B6: Taux_Marge_Local | C6: 0.12 | D6: 0.15 | E6: 0.2 | F6: Marge sur PU locaux
A7: FINANCE | B7: Taux_Marge_Chine | C7: 0.08 | D7: 0.1 | E7: 0.15 | F7: Marge sur PU importés
A8: LOGISTIQUE | B8: Taux_Transport | C8: 0.06 | D8: 0.08 | E8: 0.12 | F8: Transport maritime + terrestre
A9: LOGISTIQUE | B9: Taux_Douane | C9: 0.12 | D9: 0.15 | E9: 0.2 | F9: Droits de douane Congo
A10: LOGISTIQUE | B10: Cout_Container | C10: 2200000 | D10: 2500000 | E10: 3000000 | F10: Coût/container 20 pieds (FCFA)
A11: LOGISTIQUE | B11: Capacite_Container | C11: 30 | D11: 28 | E11: 25 | F11: Capacité utile m³/container
A12: DECISION | B12: Seuil_Decision_Import | C12: 0.03 | D12: 0.05 | E12: 0.08 | F12: Seuil taux éco pour importer
A13: DECISION | B13: Poids_Prix | C13: 0.45 | D13: 0.4 | E13: 0.35 | F13: Poids critère prix
A14: DECISION | B14: Poids_Risque | C14: 0.25 | D14: 0.3 | E14: 0.35 | F14: Poids critère risque
A15: DECISION | B15: Poids_Delai | C15: 0.2 | D15: 0.2 | E15: 0.2 | F15: Poids critère délai
A16: DECISION | B16: Poids_Volume | C16: 0.1 | D16: 0.1 | E16: 0.1 | F16: Poids critère volume

Sheet PARAM_PROJET_ID
A1: PARAM_PROJET_ID
A2: PNR_MEDICAL_CENTER

Sheet T_PROJET
A1: PROJET_ID | B1: NOM_PROJET | C1: TYPE_PROJET | D1: STATUT | E1: DATE_CREATION | F1: DEVISE | G1: MODE_SOURCING | H1: NB_LOTS
A2: PNR_MEDICAL_CENTER | B2: Centre Médical Pointe Noire | C2: Médical | D2: Etude | E2: 2026-01-01 | F2: FCFA | G2: Mixte | H2: 17

Sheet T_FAM_ARTICLE
A1: FAM_ARTICLE_ID | B1: CODE_FAM_ARTICLE | C1: LIBELLE_FAM_ARTICLE | D1: FAM_METIER_ID | E1: IMPORTABLE | F1: TAUX_MAIN_OEUVRE | G1: RISQUE_IMPORT
A2: FA_001 | B2: GROS_OEUVRE | C2: Gros Œuvre & Démolition | D2: FM_01 | E2: 0 | F2: 0.4 | G2: 0
A3: FA_002 | B3: ETANCHEITE | C3: Étanchéité | D3: FM_02 | E3: 1 | F3: 0.3 | G3: 1
A4: FA_003 | B4: ALUCOBOND | C4: Alucobond – Bardage Façade | D4: FM_02 | E4: 1 | F4: 0.2 | G4: 2
A5: FA_004 | B5: REVETEMENTS_DURS | C5: Revêtements Durs | D5: FM_03 | E5: 1 | F5: 0.2 | G5: 2
A6: FA_005 | B6: MENUISERIE_ALU | C6: Menuiserie Aluminium & Vitrerie | D6: FM_03 | E6: 1 | F6: 0.25 | G6: 2
A7: FA_006 | B7: MENUISERIE_MET | C7: Menuiserie Métallique | D7: FM_03 | E7: 1 | F7: 0.3 | G7: 2
A8: FA_007 | B8: MENUISERIE_BOIS | C8: Menuiserie Bois | D8: FM_03 | E8: 1 | F8: 0.2 | G8: 2
A9: FA_008 | B9: ELECTRICITE | C9: Électricité | D9: FM_04 | E9: 1 | F9: 0.15 | G9: 3
A10: FA_009 | B10: CLIMATISATION | C10: Climatisation | D10: FM_04 | E10: 1 | F10: 0.1 | G10: 2.5
A11: FA_010 | B11: SECURITE_INCENDIE | C11: Sécurité Incendie & Vidéo | D11: FM_04 | E11: 1 | F11: 0.25 | G11: 2
A12: FA_011 | B12: PLOMBERIE | C12: Plomberie Sanitaire | D12: FM_04 | E12: 1 | F12: 0.2 | G12: 1.5
A13: FA_012 | B13: FAUX_PLAFONDS | C13: Faux Plafonds & Cloisons | D13: FM_03 | E13: 1 | F13: 0.1 | G13: 3.5
... A18: FA_017 | B18: GROUPE_ELECTROGENE | C18: Groupe Électrogène | D18: FM_04 | E18: 1 | F18: 0.1 | G18: 3

Sheet T_FAM_METIER
A1: FAM_METIER_ID | B1: CODE_FAM_METIER | C1: LIBELLE_FAM_METIER | D1: CATEGORIE_METIER | E1: ORDRE_AFFICHAGE
A2: FM_01 | B2: STRUCTURE | C2: Structure & Gros Œuvre | D2: STRUCTURE | E2: 1
A3: FM_02 | B3: ENVELOPPE | C3: Enveloppe & Étanchéité | D3: FINITION | E3: 2
A4: FM_03 | B4: FINITION | C4: Menuiserie & Finitions | D4: FINITION | E4: 3
A5: FM_04 | B5: TECHNIQUE | C5: Corps Techniques | D5: TECHNIQUE | E5: 4

Sheet T_BATIMENT
A1: BATIMENT_ID | B1: NOM_BATIMENT | C1: PROJET_ID | D1: ORDRE_AFFICHAGE
A2: BAT_PRINCIPAL | B2: Bâtiment Principal | C2: PNR_MEDICAL_CENTER | D2: 1
A3: BAT_ANNEXE | B3: Bâtiment Annexe | C3: PNR_MEDICAL_CENTER | D3: 0

Sheet T_MAPPING_DOMAINE_FAM
A1: DOMAINE | B1: FAM_ARTICLE_ID
A2: INSTALL | B2: FA_001
A3: DEMO | B3: FA_001
A4: MACON | B4: FA_001
A5: ETANCH | B5: FA_002
A6: ALUCOBOND | B6: FA_003
A7: REVET | B7: FA_004
A8: MEN | B8: FA_005
A9: ELEC | B9: FA_008
A10: CLIM | B10: FA_009
A11: SSI | B11: FA_010
A12: VIDEO | B12: FA_015
... A17: CDA | B17: FA_010

Sheet ---02_RAW---

Sheet ANALYTICS_PARETO_IMPORT

Sheet CLEAN_METRE_AGG
A1: PROJET_ID | B1: CODE_BPU | C1: DESIGNATION | D1: LOT | E1: BATIMENT_ID | F1: NIVEAU_ID | G1: UNITE | H1: QTE
A2: PNR_MEDICAL_CENTER | B2: BPU-INSTALL-GEN-MOB-001 | C2: Mobilisation | D2: LOT 1 | E2: BAT_PRINCIPAL | F2: GLOBAL | G2: FORFAIT | H2: 1
A3: PNR_MEDICAL_CENTER | B3: BPU-INSTALL-GEN-BASEVIE-002 | C3: Bureau de chantier, atelier, baraquement et clôture provisoire | D3: LOT 1 | E3: BAT_PRINCIPAL | F3: GLOBAL | G3: FORFAIT | H3: 1
A4: PNR_MEDICAL_CENTER | B4: BPU-INSTALL-GEN-CONC-003 | C4: Abonnement, mensualité concessionnaires | D4: LOT 1 | E4: BAT_PRINCIPAL | F4: GLOBAL | G4: FORFAIT | H4: 1
A5: PNR_MEDICAL_CENTER | B5: BPU-INSTALL-GEN-MAT-004 | C5: Matériel de chantier (engins, manutention etc) | D5: LOT 1 | E5: BAT_PRINCIPAL | F5: GLOBAL | G5: FORFAIT | H5: 1
A6: PNR_MEDICAL_CENTER | B6: BPU-INSTALL-GEN-DIVERS-005 | C6: Divers (sécurité, ASE, panneau de chantier...) | D6: LOT 1 | E6: BAT_PRINCIPAL | F6: GLOBAL | G6: FORFAIT | H6: 1
A7: PNR_MEDICAL_CENTER | B7: BPU-INSTALL-GEN-ETUDE-006 | C7: Études techniques et Essais | D7: LOT 1 | E7: BAT_PRINCIPAL | F7: GLOBAL | G7: FORFAIT | H7: 1
A8: PNR_MEDICAL_CENTER | B8: BPU-INSTALL-GEN-AXE-007 | C8: Ensemble des axes necessaires | D8: LOT 1 | E8: BAT_PRINCIPAL | F8: GLOBAL | G8: FORFAIT | H8: 1
A9: PNR_MEDICAL_CENTER | B9: BPU-DEMO-MUR-ESC-RDC-008 | C9: Démolition des murs et l'escalier (RDC) | D9: LOT 1 | E9: BAT_PRINCIPAL | F9: RDC | G9: FORFAIT | H9: 1
A10: PNR_MEDICAL_CENTER | B10: BPU-DEMO-MUR-ESC-ET1-ANNEXE-009 | C10: Démolition des murs et l'escalier y compris la dalle existente bâtiment annexe (ÉTAGE 1) | D10: LOT 1 | E10: BAT_ANNEXE | F10: ETAGE 1 | G10: FORFAIT | H10: 1
A11: PNR_MEDICAL_CENTER | B11: BPU-DEMO-MUR-ESC-ET2-010 | C11: Démolition des murs et l'escalier (ÉTAGE 2) | D11: LOT 1 | E11: BAT_PRINCIPAL | F11: ETAGE 2 | G11: FORFAIT | H11: 1
A12: PNR_MEDICAL_CENTER | B12: BPU-DEMO-EVAC-GRAVAT-011 | C12: Évacuation des gravats hors site | D12: LOT 1 | E12: BAT_PRINCIPAL | F12: GLOBAL | G12: FORFAIT | H12: 1
A13: PNR_MEDICAL_CENTER | B13: BPU-DEMO-DECAP-CARREAU-012 | C13: Décapage des carreaux sol existants en RDC | D13: LOT 1 | E13: BAT_PRINCIPAL | F13: RDC | G13: M2 | H13: 460
... A301: PNR_MEDICAL_CENTER | B301: BPU-PEINT-PLAF-INT-PANTEX-188 | C301: Peinture intérieure comprissant une impression en pantiprim, 02 couches d'enduits repassés et 02 couches de finitions en pante 800 | D301: LOT 14 | E301: BAT_PRINCIPAL | F301: DUPLEX 1 | G301: M2 | H301: 182

Sheet RAW__METRE
A1: PROJET_ID | B1: CODE_BPU | C1: DESIGNATION | D1: LOT | E1: BATIMENT_ID | F1: NIVEAU_ID | G1: UNITE | H1: QTE | I1: DATE_MAJ
A2: PROJ-MED-PNR-2025 | B2: BPU-INSTALL-GEN-MOB-001 | C2: Mobilisation | D2: LOT 1 | E2: PRINCIPAL | F2: GLOBAL | G2: FORFAIT | H2: 1 | I2: 46084
A3: PROJ-MED-PNR-2025 | B3: BPU-INSTALL-GEN-BASEVIE-002 | C3: Bureau de chantier, atelier, baraquement et clôture provisoire | D3: LOT 1 | E3: PRINCIPAL | F3: GLOBAL | G3: FORFAIT | H3: 1 | I3: 46084
A4: PROJ-MED-PNR-2025 | B4: BPU-INSTALL-GEN-CONC-003 | C4: Abonnement, mensualité concessionnaires | D4: LOT 1 | E4: PRINCIPAL | F4: GLOBAL | G4: FORFAIT | H4: 1 | I4: 46084
A5: PROJ-MED-PNR-2025 | B5: BPU-INSTALL-GEN-MAT-004 | C5: Matériel de chantier (engins, manutention etc) | D5: LOT 1 | E5: PRINCIPAL | F5: GLOBAL | G5: FORFAIT | H5: 1 | I5: 46084
A6: PROJ-MED-PNR-2025 | B6: BPU-INSTALL-GEN-DIVERS-005 | C6: Divers (sécurité, ASE, panneau de chantier...) | D6: LOT 1 | E6: PRINCIPAL | F6: GLOBAL | G6: FORFAIT | H6: 1 | I6: 46084
A7: PROJ-MED-PNR-2025 | B7: BPU-INSTALL-GEN-ETUDE-006 | C7: Études techniques et Essais | D7: LOT 1 | E7: PRINCIPAL | F7: GLOBAL | G7: FORFAIT | H7: 1 | I7: 46084
A8: PROJ-MED-PNR-2025 | B8: BPU-INSTALL-GEN-AXE-007 | C8: Ensemble des axes necessaires | D8: LOT 1 | E8: PRINCIPAL | F8: GLOBAL | G8: FORFAIT | H8: 1 | I8: 46084
A9: PROJ-MED-PNR-2025 | B9: BPU-DEMO-MUR-ESC-RDC-008 | C9: Démolition des murs et l'escalier (RDC) | D9: LOT 1 | E9: PRINCIPAL | F9: RDC | G9: FORFAIT | H9: 1 | I9: 46084
A10: PROJ-MED-PNR-2025 | B10: BPU-DEMO-MUR-ESC-ET1-ANNEXE-009 | C10: Démolition des murs et l'escalier y compris la dalle existente bâtiment annexe (ÉTAGE 1) | D10: LOT 1 | E10: ANNEXE | F10: ETAGE 1 | G10: FORFAIT | H10: 1 | I10: 46084
A11: PROJ-MED-PNR-2025 | B11: BPU-DEMO-MUR-ESC-ET2-010 | C11: Démolition des murs et l'escalier (ÉTAGE 2) | D11: LOT 1 | E11: PRINCIPAL | F11: ETAGE 2 | G11: FORFAIT | H11: 1 | I11: 46084
A12: PROJ-MED-PNR-2025 | B12: BPU-DEMO-EVAC-GRAVAT-011 | C12: Évacuation des gravats hors site | D12: LOT 1 | E12: PRINCIPAL | F12: GLOBAL | G12: FORFAIT | H12: 1 | I12: 46084
A13: PROJ-MED-PNR-2025 | B13: BPU-DEMO-DECAP-CARREAU-012 | C13: Décapage des carreaux sol existants en RDC | D13: LOT 1 | E13: PRINCIPAL | F13: RDC | G13: M2 | H13: 460 | I13: 46084
... A302: PROJ-MED-PNR-2025 | B302: BPU-PEINT-PLAF-INT-PANTEX-188 | C302: Peinture intérieure comprissant une impression en pantiprim, 02 couches d'enduits repassés et 02 couches de finitions en pante 800 | D302: LOT 14 | E302: PRINCIPAL | F302: DUPLEX 1 | G302: M2 | H302: 182 | I302: 46084

Sheet CLEAN__LOT
A1: LOT_ID | B1: CODE_LOT | C1: NOM_LOT | D1: DESCRIPTION_LOT | E1: ORDRE_LOT | F1: TYPE_LOT
A2: 1 | B2: L01 | C2: LOT 1 | D2: Gros œuvre et démolition | E2: 1 | F2: STRUCTURE
A3: 2 | B3: L02 | C3: LOT 2 | D3: Étanchéité | E3: 2 | F3: ARCHI
A4: 3 | B4: L03 | C4: LOT 3 | D4: Revêtement durs | E4: 3 | F4: ARCHI
A5: 4 | B5: L04 | C5: LOT 4 | D5: Menuiserie aluminium et vitrerie | E5: 4 | F5: ARCHI
A6: 5 | B6: L05 | C6: LOT 5 | D6: Menuiserie métallique et ferronnerie | E6: 5 | F6: ARCHI
A7: 6 | B7: L06 | C7: LOT 6 | D7: Menuiserie bois | E7: 6 | F7: ARCHI
A8: 7 | B8: L07 | C8: LOT 7 | D8: Electricité | E8: 7 | F8: TECH
A9: 8 | B9: L08 | C9: LOT 8 | D9: Climatisation | E9: 8 | F9: TECH
A10: 9 | B10: L09 | C10: LOT 9 | D10: Sécurité incendie et vidéo surveillance | E10: 9 | F10: TECH
A11: 10 | B11: L10 | C11: LOT 10 | D11: Plomberie sanitaire | E11: 10 | F11: TECH
A12: 11 | B12: L11 | C12: LOT 11 | D12: Faux plafond et cloisons BA13 | E12: 11 | F12: ARCHI
A13: 12 | B13: L12 | C13: L0T 12 | D13: Ascenseur | E13: 12 | F13: EQUIPEMENT
... A15: 14 | B15: L14 | C15: LOT 14 | D15: Peinture | E15: 14 | F15: FINITION

Sheet RAW__LOT
A1: LOT_ID | B1: CODE_LOT | C1: NOM_LOT | D1: DESCRIPTION_LOT | E1: ORDRE_LOT | F1: TYPE_LOT
A2: 1 | B2: L01 | C2: LOT 1 | D2: Gros œuvre et démolition | E2: 1 | F2: STRUCTURE
A3: 2 | B3: L02 | C3: LOT 2 | D3: Étanchéité | E3: 2 | F3: ARCHI
A4: 3 | B4: L03 | C4: LOT 3 | D4: Revêtement durs | E4: 3 | F4: ARCHI
A5: 4 | B5: L04 | C5: LOT 4 | D5: Menuiserie aluminium et vitrerie | E5: 4 | F5: ARCHI
A6: 5 | B6: L05 | C6: LOT 5 | D6: Menuiserie métallique et ferronnerie | E6: 5 | F6: ARCHI
A7: 6 | B7: L06 | C7: LOT 6 | D7: Menuiserie bois | E7: 6 | F7: ARCHI
A8: 7 | B8: L07 | C8: LOT 7 | D8: Electricité | E8: 7 | F8: TECH
A9: 8 | B9: L08 | C9: LOT 8 | D9: Climatisation | E9: 8 | F9: TECH
A10: 9 | B10: L09 | C10: LOT 9 | D10: Sécurité incendie et vidéo surveillance | E10: 9 | F10: TECH
A11: 10 | B11: L10 | C11: LOT 10 | D11: Plomberie sanitaire | E11: 10 | F11: TECH
A12: 11 | B12: L11 | C12: LOT 11 | D12: Faux plafond et cloisons BA13 | E12: 11 | F12: ARCHI
A13: 12 | B13: L12 | C13: L0T 12 | D13: Ascenseur | E13: 12 | F13: EQUIPEMENT
... A15: 14 | B15: L14 | C15: LOT 14 | D15: Peinture | E15: 14 | F15: FINITION

Sheet T_LOT
A1: LOT_ID | B1: CODE_LOT | C1: NOM_LOT | D1: DESCRIPTION_LOT | E1: ORDRE_LOT | F1: TYPE_LOT
A2: 1 | B2: L01 | C2: LOT 1 | D2: Gros œuvre et démolition | E2: 1 | F2: STRUCTURE
A3: 2 | B3: L02 | C3: LOT 2 | D3: Étanchéité | E3: 2 | F3: ARCHI
A4: 3 | B4: L03 | C4: LOT 3 | D4: Revêtement durs | E4: 3 | F4: ARCHI
A5: 4 | B5: L04 | C5: LOT 4 | D5: Menuiserie aluminium et vitrerie | E5: 4 | F5: ARCHI
A6: 5 | B6: L05 | C6: LOT 5 | D6: Menuiserie métallique et ferronnerie | E6: 5 | F6: ARCHI
A7: 6 | B7: L06 | C7: LOT 6 | D7: Menuiserie bois | E7: 6 | F7: ARCHI
A8: 7 | B8: L07 | C8: LOT 7 | D8: Electricité | E8: 7 | F8: TECH
A9: 8 | B9: L08 | C9: LOT 8 | D9: Climatisation | E9: 8 | F9: TECH
A10: 9 | B10: L09 | C10: LOT 9 | D10: Sécurité incendie et vidéo surveillance | E10: 9 | F10: TECH
A11: 10 | B11: L10 | C11: LOT 10 | D11: Plomberie sanitaire | E11: 10 | F11: TECH
A12: 11 | B12: L11 | C12: LOT 11 | D12: Faux plafond et cloisons BA13 | E12: 11 | F12: ARCHI
A13: 12 | B13: L12 | C13: L0T 12 | D13: Ascenseur | E13: 12 | F13: EQUIPEMENT
... A15: 14 | B15: L14 | C15: LOT 14 | D15: Peinture | E15: 14 | F15: FINITION

Sheet T_RAW__LOT
A1: LOT_ID | B1: CODE_LOT | C1: NOM_LOT | D1: DESCRIPTION_LOT | E1: ORDRE_LOT | F1: TYPE_LOT
A2: 1 | B2: L01 | C2: LOT 1 | D2: Gros œuvre et démolition | E2: 1 | F2: STRUCTURE
A3: 2 | B3: L02 | C3: LOT 2 | D3: Étanchéité | E3: 2 | F3: ARCHI
A4: 3 | B4: L03 | C4: LOT 3 | D4: Revêtement durs | E4: 3 | F4: ARCHI
A5: 4 | B5: L04 | C5: LOT 4 | D5: Menuiserie aluminium et vitrerie | E5: 4 | F5: ARCHI
A6: 5 | B6: L05 | C6: LOT 5 | D6: Menuiserie métallique et ferronnerie | E6: 5 | F6: ARCHI
A7: 6 | B7: L06 | C7: LOT 6 | D7: Menuiserie bois | E7: 6 | F7: ARCHI
A8: 7 | B8: L07 | C8: LOT 7 | D8: Electricité | E8: 7 | F8: TECH
A9: 8 | B9: L08 | C9: LOT 8 | D9: Climatisation | E9: 8 | F9: TECH
A10: 9 | B10: L09 | C10: LOT 9 | D10: Sécurité incendie et vidéo surveillance | E10: 9 | F10: TECH
A11: 10 | B11: L10 | C11: LOT 10 | D11: Plomberie sanitaire | E11: 10 | F11: TECH
A12: 11 | B12: L11 | C12: LOT 11 | D12: Faux plafond et cloisons BA13 | E12: 11 | F12: ARCHI
A13: 12 | B13: L12 | C13: L0T 12 | D13: Ascenseur | E13: 12 | F13: EQUIPEMENT
... A15: 14 | B15: L14 | C15: LOT 14 | D15: Peinture | E15: 14 | F15: FINITION

Sheet RAW_BPU_LOCAL
A1: CODE_BPU | B1: DESIGNATION | C1: LOT | D1: UNITE | E1: PU_LOCAL | F1: DATE_REFERENCE | G1: SOURCE | H1: FAM_ARTICLE_ID | I1: PROJET_ID | J1: TYPE_COUT | K1: ACTIF
A2: BPU-INSTALL-GEN-MOB-001 | B2: Mobilisation | C2: LOT 1 | D2: FORFAIT | E2: 4755250 | F2: 45882 | G2: DQE_MEDICAL CENTER_13-08-2025 | I2: PNMC_2025 | J2: MATERIAU | K2: 1
A3: BPU-INSTALL-GEN-BASEVIE-002 | B3: Bureau de chantier, atelier, baraquement et clôture provisoire | C3: LOT 1 | D3: FORFAIT | E3: 3758730 | F3: 45882 | G3: DQE_MEDICAL CENTER_13-08-2025 | I3: PNMC_2025 | J3: MATERIAU | K3: 1
A4: BPU-INSTALL-GEN-CONC-003 | B4: Abonnement, mensualité concessionnaires | C4: LOT 1 | D4: FORFAIT | E4: 2507000 | F4: 45882 | G4: DQE_MEDICAL CENTER_13-08-2025 | I4: PNMC_2025 | J4: MATERIAU | K4: 1
A5: BPU-INSTALL-GEN-MAT-004 | B5: Matériel de chantier (engins, manutention etc) | C5: LOT 1 | D5: FORFAIT | E5: 4213438 | F5: 45882 | G5: DQE_MEDICAL CENTER_13-08-2025 | I5: PNMC_2025 | J5: MATERIAU | K5: 1
A6: BPU-INSTALL-GEN-DIVERS-005 | B6: Divers (sécurité, ASE, panneau de chantier...) | C6: LOT 1 | D6: FORFAIT | E6: 4945000 | F6: 45882 | G6: DQE_MEDICAL CENTER_13-08-2025 | I6: PNMC_2025 | J6: MATERIAU | K6: 1
A7: BPU-INSTALL-GEN-ETUDE-006 | B7: Études techniques et Essais | C7: LOT 1 | D7: FORFAIT | E7: 4795500 | F7: 45882 | G7: DQE_MEDICAL CENTER_13-08-2025 | I7: PNMC_2025 | J7: MATERIAU | K7: 1
A8: BPU-INSTALL-GEN-AXE-007 | B8: Ensemble des axes necessaires | C8: LOT 1 | D8: FORFAIT | E8: 1265000 | F8: 45882 | G8: DQE_MEDICAL CENTER_13-08-2025 | I8: PNMC_2025 | J8: MATERIAU | K8: 1
A9: BPU-DEMO-MUR-ESC-RDC-008 | B9: Démolition des murs et l'escalier (RDC) | C9: LOT 1 | D9: FORFAIT | E9: 1725000 | F9: 45882 | G9: DQE_MEDICAL CENTER_13-08-2025 | I9: PNMC_2025 | J9: MATERIAU | K9: 1
A10: BPU-DEMO-MUR-ESC-ET1-ANNEXE-009 | B10: Démolition des murs et l'escalier y compris la dalle existente bâtiment annexe (ÉTAGE 1) | C10: LOT 1 | D10: FORFAIT | E10: 2587500 | F10: 45882 | G10: DQE_MEDICAL CENTER_13-08-2025 | I10: PNMC_2025 | J10: MATERIAU | K10: 1
A11: BPU-DEMO-MUR-ESC-ET2-010 | B11: Démolition des murs et l'escalier (ÉTAGE 2) | C11: LOT 1 | D11: FORFAIT | E11: 1725000 | F11: 45882 | G11: DQE_MEDICAL CENTER_13-08-2025 | I11: PNMC_2025 | J11: MATERIAU | K11: 1
A12: BPU-DEMO-EVAC-GRAVAT-011 | B12: Évacuation des gravats hors site | C12: LOT 1 | D12: FORFAIT | E12: 552000 | F12: 45882 | G12: DQE_MEDICAL CENTER_13-08-2025 | I12: PNMC_2025 | J12: MATERIAU | K12: 1
A13: BPU-DEMO-DECAP-CARREAU-012 | B13: Décapage des carreaux sol existants en RDC | C13: LOT 1 | D13: M2 | E13: 5750 | F13: 45882 | G13: DQE_MEDICAL CENTER_13-08-2025 | I13: PNMC_2025 | J13: MATERIAU | K13: 1
... A168: BPU-PLOMB-SURPRESSION-167 | B168: Station de surpression au complet comprenant les 2 pompes de surpression sanitaire de 27 m3/h - 35 mCE y compris une vessie de 300 litres, accessoires de raccordement et équipements de la bâche à eau | C168: LOT 10 | D168: FORFAIT | E168: 1725000 | F168: 45882 | G168: DQE_MEDICAL CENTER_13-08-2025 | I168: PNMC_2025 | J168: MATERIAU | K168: 1
A169: BPU-PLOMB-RACC-BACHE-168 | B169: Raccordement des bâches à eau y compris raccordement au réseau avec tous les accessoires (vannes | C169: LOT 11 | D169: FORFAIT | E169: 402500 | F169: 45883 | G169: DQE_MEDICAL CENTER_13-08-2026 | H169: 45882 | I169: PNMC_2025 | J169: MATERIAU | K169: 1
A170: BPU-PLOMB-TAMPON-FONTE-169 | B170: Tampon de fermeture en fonte pour fosses | C170: LOT 10 | D170: FORFAIT | E170: 402500 | F170: 45882 | G170: DQE_MEDICAL CENTER_13-08-2025 | I170: PNMC_2025 | J170: MATERIAU | K170: 1
A171: BPU-PLOMB-SIPHON-SOL-D63-170 | B171: Siphon de sol D63 | C171: LOT 10 | D171: FORFAIT | E171: 11500 | F171: 45882 | G171: DQE_MEDICAL CENTER_13-08-2025 | I171: PNMC_2025 | J171: MATERIAU | K171: 1
A172: BPU-PLOMB-COMPT-CLAPET-171 | B172: Ensemble vanne, compteur, clapet anti- | C172: LOT 10 | D172: FORFAIT | E172: 862500 | F172: 45882 | G172: DQE_MEDICAL CENTER_13-08-2025 | I172: PNMC_2025 | J172: MATERIAU | K172: 1
A173: BPU-PLOMB-VMC-CAIS-01-172 | B173: Caisson de Ventilation Mécanique Contrôlée | C173: LOT 10 | D173: FORFAIT | E173: 575000 | F173: 45882 | G173: DQE_MEDICAL CENTER_13-08-2025 | I173: PNMC_2025 | J173: MATERIAU | K173: 1
A174: BPU-PLOMB-VMC-CAIS-02-173 | B174: Caisson de Ventilation Mécanique Contrôlée | C174: LOT 10 | D174: FORFAIT | E174: 402500 | F174: 45882 | G174: DQE_MEDICAL CENTER_13-08-2025 | I174: PNMC_2025 | J174: MATERIAU | K174: 1
A175: BPU-PLOMB-BOUCHE-EXTR-ALIZE-01-174 | B175: Bouche d'extraction de type Alizé | C175: LOT 10 | D175: FORFAIT | E175: 26450 | F175: 45882 | G175: DQE_MEDICAL CENTER_13-08-2025 | I175: PNMC_2025 | J175: MATERIAU | K175: 1
A176: BPU-PLOMB-BOUCHE-EXTR-ALIZE-02-175 | B176: Bouche d'extraction de type Alizé | C176: LOT 10 | D176: FORFAIT | E176: 28750 | F176: 45882 | G176: DQE_MEDICAL CENTER_13-08-2025 | I176: PNMC_2025 | J176: MATERIAU | K176: 1
A177: BPU-PLOMB-CONDUIT-SPIR-AC-GALV-D125-176 | B177: Conduit spiralé en acier galvanisé D125 | C177: LOT 10 | D177: ML | E177: 14375 | F177: 45882 | G177: DQE_MEDICAL CENTER_13-08-2025 | I177: PNMC_2025 | J177: MATERIAU | K177: 1
A178: BPU-PLOMB-CONDUIT-SPIR-AC-GALV-D160-177 | B178: Conduit spiralé en acier galvanisé D160 | C178: LOT 10 | D178: ML | E178: 19550 | F178: 45882 | G178: DQE_MEDICAL CENTER_13-08-2025 | I178: PNMC_2025 | J178: MATERIAU | K178: 1
A179: BPU-PLOMB-CONDUIT-SPIR-AC-GALV-D200-178 | B179: Conduit spiralé en acier galvanisé D200 | C179: LOT 10 | D179: ML | E179: 29210 | F179: 45882 | G179: DQE_MEDICAL CENTER_13-08-2025 | I179: PNMC_2025 | J179: MATERIAU | K179: 1
A180: BPU-FP-FP-ISORELLE-179 | B180: Faux plafonds en plaquette d'isorelle ou | C180: LOT 11 | D180: M2 | E180: 26450 | F180: 45882 | G180: DQE_MEDICAL CENTER_13-08-2025 | I180: PNMC_2025 | J180: MATERIAU | K180: 1
A181: BPU-FP-CLOISON-BA13-LV-180 | B181: Cloison en BA 13 avec laine de verre | C181: LOT 11 | D181: M2 | E181: 39100 | F181: 45882 | G181: DQE_MEDICAL CENTER_13-08-2025 | I181: PNMC_2025 | J181: MATERIAU | K181: 1
... A189: BPU-PEINT-PLAF-INT-PANTEX-188 | B189: Peinture intérieure comprissant une impression en pantiprim, 02 couches d'enduits repassés et 02 couches de finitions en pante 800 | C189: LOT 14 | D189: M2 | E189: 6325 | F189: 45882 | G189: DQE_MEDICAL CENTER_13-08-2025 | I189: PNMC_2025 | J189: MATERIAU | K189: 1

Sheet TEST_COHERENCE_PRIX
A1: CODE_BPU | B1: DESIGNATION | C1: LOT | D1: BATIMENT_ID | E1: NIVEAU_ID | F1: UNITE | G1: QTE | H1: DATE_MAJ | I1: PROJET_ID | J1: PU_LOCAL | K1: PU_CHINE | L1: PRIX_LOCAL_OK | M1: PRIX_CHINE_OK
A2: BPU-INSTALL-GEN-MOB-001 | B2: Mobilisation | C2: LOT 1 | D2: BAT_PRINCIPAL | E2: GLOBAL | F2: FORFAIT | G2: 1 | H2: 46084 | I2: PNR_MEDICAL_CENTER | J2: 4755250 | K2: 4755250 | L2: 1 | M2: 1
A3: BPU-INSTALL-GEN-BASEVIE-002 | B3: Bureau de chantier, atelier, baraquement et clôture provisoire | C3: LOT 1 | D3: BAT_PRINCIPAL | E3: GLOBAL | F3: FORFAIT | G3: 1 | H3: 46084 | I3: PNR_MEDICAL_CENTER | J3: 3758730 | K3: 3758730 | L3: 1 | M3: 1
A4: BPU-INSTALL-GEN-CONC-003 | B4: Abonnement, mensualité concessionnaires | C4: LOT 1 | D4: BAT_PRINCIPAL | E4: GLOBAL | F4: FORFAIT | G4: 1 | H4: 46084 | I4: PNR_MEDICAL_CENTER | J4: 2507000 | K4: 2507000 | L4: 1 | M4: 1
A5: BPU-INSTALL-GEN-MAT-004 | B5: Matériel de chantier (engins, manutention etc) | C5: LOT 1 | D5: BAT_PRINCIPAL | E5: GLOBAL | F5: FORFAIT | G5: 1 | H5: 46084 | I5: PNR_MEDICAL_CENTER | J5: 4213438 | K5: 4213438 | L5: 1 | M5: 1
A6: BPU-INSTALL-GEN-DIVERS-005 | B6: Divers (sécurité, ASE, panneau de chantier...) | C6: LOT 1 | D6: BAT_PRINCIPAL | E6: GLOBAL | F6: FORFAIT | G6: 1 | H6: 46084 | I6: PNR_MEDICAL_CENTER | J6: 4945000 | K6: 4945000 | L6: 1 | M6: 1
A7: BPU-INSTALL-GEN-ETUDE-006 | B7: Études techniques et Essais | C7: LOT 1 | D7: BAT_PRINCIPAL | E7: GLOBAL | F7: FORFAIT | G7: 1 | H7: 46084 | I7: PNR_MEDICAL_CENTER | J7: 4795500 | K7: 4795500 | L7: 1 | M7: 1
A8: BPU-INSTALL-GEN-AXE-007 | B8: Ensemble des axes necessaires | C8: LOT 1 | D8: BAT_PRINCIPAL | E8: GLOBAL | F8: FORFAIT | G8: 1 | H8: 46084 | I8: PNR_MEDICAL_CENTER | J8: 1265000 | K8: 1265000 | L8: 1 | M8: 1
A9: BPU-DEMO-MUR-ESC-RDC-008 | B9: Démolition des murs et l'escalier (RDC) | C9: LOT 1 | D9: BAT_PRINCIPAL | E9: RDC | F9: FORFAIT | G9: 1 | H9: 46084 | I9: PNR_MEDICAL_CENTER | J9: 1725000 | K9: 1725000 | L9: 1 | M9: 1
A10: BPU-DEMO-MUR-ESC-ET1-ANNEXE-009 | B10: Démolition des murs et l'escalier y compris la dalle existente bâtiment annexe (ÉTAGE 1) | C10: LOT 1 | D10: BAT_ANNEXE | E10: ETAGE 1 | F10: FORFAIT | G10: 1 | H10: 46084 | I10: PNR_MEDICAL_CENTER | J10: 2587500 | K10: 2587500 | L10: 1 | M10: 1
A11: BPU-DEMO-MUR-ESC-ET2-010 | B11: Démolition des murs et l'escalier (ÉTAGE 2) | C11: LOT 1 | D11: BAT_PRINCIPAL | E11: ETAGE 2 | F11: FORFAIT | G11: 1 | H11: 46084 | I11: PNR_MEDICAL_CENTER | J11: 1725000 | K11: 1725000 | L11: 1 | M11: 1
A12: BPU-DEMO-EVAC-GRAVAT-011 | B12: Évacuation des gravats hors site | C12: LOT 1 | D12: BAT_PRINCIPAL | E12: GLOBAL | F12: FORFAIT | G12: 1 | H12: 46084 | I12: PNR_MEDICAL_CENTER | J12: 552000 | K12: 552000 | L12: 1 | M12: 1
A13: BPU-DEMO-DECAP-CARREAU-012 | B13: Décapage des carreaux sol existants en RDC | C13: LOT 1 | D13: BAT_PRINCIPAL | E13: RDC | F13: M2 | G13: 460 | H13: 46084 | I13: PNR_MEDICAL_CENTER | J13: 5750 | L13: 1 | M13: 0
A14: BPU-MACON-FOND-BET-PROP-013 | B14: Béton de propreté | C14: LOT 1 | D14: BAT_PRINCIPAL | E14: FONDATIONS | F14: M3 | G14: 3.07 | H14: 46084 | I14: PNR_MEDICAL_CENTER | J14: 338720 | K14: 338720 | L14: 1 | M14: 1
A15: BPU-MACON-FOND-BET-400-014 | B15: Béton 400 hydr | C15: LOT 1 | D15: BAT_PRINCIPAL | E15: FONDATIONS | F15: M3 | G15: 4.36 | H15: 46084 | I15: PNR_MEDICAL_CENTER | J15: 189175 | K15: 189175 | L15: 1 | M15: 1
A16: BPU-MACON-FOND-COF-015 | B16: Coffrage | C16: LOT 1 | D16: BAT_PRINCIPAL | E16: FONDATIONS | F16: M2 | G16: 15.84 | H16: 46084 | I16: PNR_MEDICAL_CENTER | J16: 5750 | K16: 3350 | L16: 1 | M16: 1
A17: BPU-MACON-FOND-AC-016 | B17: Acier | C17: LOT 1 | D17: BAT_PRINCIPAL | E17: FONDATIONS | F17: KG | G17: 436 | H17: 46084 | I17: PNR_MEDICAL_CENTER | J17: 1380 | K17: 370 | L17: 1 | M17: 1
A18: BPU-MACON-SSO-AGGL-PLEIN-026 | B18: Agglos pleins 20x20x50 | C18: LOT 1 | D18: BAT_PRINCIPAL | E18: FONDATIONS | F18: M2 | G18: 78.98 | H18: 46084 | I18: PNR_MEDICAL_CENTER | J18: 12180 | K18: 12180 | L18: 1 | M18: 1
A19: BPU-MACON-ELEV-POT-BET-400-017 | B19: Béton 400 hydr (Amorces poteaux) | C19: LOT 1 | D19: BAT_PRINCIPAL | E19: FONDATIONS | F19: M3 | G19: 1.65 | H19: 46084 | I19: PNR_MEDICAL_CENTER | J19: 189175 | L19: 1 | M19: 0
A20: BPU-MACON-AGGL-CREUX-20-046 | B20: Agglos creux 20x20x50 | C20: LOT 1 | D20: BAT_PRINCIPAL | E20: RDC | F20: M2 | G20: 1 | H20: 46084 | I20: PNR_MEDICAL_CENTER | J20: 11185 | K20: 11185 | L20: 1 | M20: 1
A21: BPU-MACON-ELEV-POT-COF-018 | B21: Coffrage (Amorces poteaux) | C21: LOT 1 | D21: BAT_PRINCIPAL | E21: FONDATIONS | F21: M2 | G21: 26.4 | H21: 46084 | I21: PNR_MEDICAL_CENTER | J21: 5750 | L21: 1 | M21: 0
A22: BPU-MACON-END-INT-EXT-047 | B22: Enduits intérieurs et extérieurs sur murs | C22: LOT 1 | D22: BAT_PRINCIPAL | E22: RDC | F22: M2 | G22: 1 | H22: 46084 | I22: PNR_MEDICAL_CENTER | J22: 3827 | K22: 3827 | L22: 1 | M22: 1
A23: BPU-MACON-ELEV-POT-AC-019 | B23: Acier (Amorces poteaux) | C23: LOT 1 | D23: BAT_PRINCIPAL | E23: FONDATIONS | F23: KG | G23: 198 | H23: 46084 | I23: PNR_MEDICAL_CENTER | J23: 1380 | L23: 1 | M23: 0
A24: BPU-MACON-END-SOUS-PLF-048 | B24: Enduits sous plafond | C24: LOT 1 | D24: BAT_PRINCIPAL | E24: RDC | F24: M2 | G24: 1 | H24: 46084 | I24: PNR_MEDICAL_CENTER | J24: 3827 | K24: 3827 | L24: 1 | M24: 1
A25: BPU-MACON-ELEV-LONG-BET-400-020 | B25: Béton 400 hydr (Longrines) | C25: LOT 1 | D25: BAT_PRINCIPAL | E25: FONDATIONS | F25: M3 | G25: 3.72 | H25: 46084 | I25: PNR_MEDICAL_CENTER | J25: 189175 | L25: 1 | M25: 0
A26: BPU-ETANCH-TERR-ACC-FORME-059 | B26: Forme de pente | C26: LOT 2 | D26: BAT_PRINCIPAL | E26: DUPLEX 1 | F26: M2 | G26: 320 | H26: 46084 | I26: PNR_MEDICAL_CENTER | J26: 11793 | K26: 11793 | L26: 1 | M26: 1
A27: BPU-MACON-ELEV-LONG-COF-021 | B27: Coffrage (Longrines) | C27: LOT 1 | D27: BAT_PRINCIPAL | E27: FONDATIONS | F27: M2 | G27: 37.33 | H27: 46084 | I27: PNR_MEDICAL_CENTER | J27: 5750 | L27: 1 | M27: 0
A28: BPU-ETANCH-TERR-ACC-BI-060 | B28: Revêtement bicouche sous protection lourde | C28: LOT 2 | D28: BAT_PRINCIPAL | E28: DUPLEX 1 | F28: M2 | G28: 320 | H28: 46084 | I28: PNR_MEDICAL_CENTER | J28: 34552 | K28: 6100 | L28: 1 | M28: 1
A29: BPU-MACON-ELEV-LONG-AC-022 | B29: Acier (Longrines) | C29: LOT 1 | D29: BAT_PRINCIPAL | E29: FONDATIONS | F29: KG | G29: 484 | H29: 46084 | I29: PNR_MEDICAL_CENTER | J29: 1380 | L29: 1 | M29: 0
A30: BPU-ETANCH-TERR-ACC-RELEV-061 | B30: Relevé d'étanchéité h=50 cm | C30: LOT 2 | D30: BAT_PRINCIPAL | E30: DUPLEX 1 | F30: ML | G30: 120 | H30: 46084 | I30: PNR_MEDICAL_CENTER | J30: 8641 | K30: 3050 | L30: 1 | M30: 1
A31: BPU-MACON-ELEV-DALL-BET-023 | B31: Béton (Dallage sol) | C31: LOT 1 | D31: BAT_PRINCIPAL | E31: FONDATIONS | F31: M3 | G31: 33.2 | H31: 46084 | I31: PNR_MEDICAL_CENTER | J31: 189175 | L31: 1 | M31: 0
A32: BPU-ETANCH-TERR-INACC-FORME-062 | B32: Forme de pente | C32: LOT 2 | D32: BAT_PRINCIPAL | E32: DUPLEX 1 | F32: M2 | G32: 56.75 | H32: 46084 | I32: PNR_MEDICAL_CENTER | J32: 11793 | K32: 11793 | L32: 1 | M32: 1
A33: BPU-ETANCH-TERR-INACC-FORME-062 | B33: Forme de pente | C33: LOT 2 | D33: BAT_PRINCIPAL | E33: TERRASSE | F33: M2 | G33: 83 | H33: 46084 | I33: PNR_MEDICAL_CENTER | J33: 11793 | K33: 11793 | L33: 1 | M33: 1
A34: BPU-ETANCH-TERR-INACC-FORME-062 | B34: Forme de pente | C34: LOT 2 | D34: BAT_ANNEXE | E34: TERRASSE | F34: M2 | G34: 231 | H34: 46084 | I34: PNR_MEDICAL_CENTER | J34: 11793 | K34: 11793 | L34: 1 | M34: 1
A35: BPU-MACON-ELEV-DALL-COF-024 | B35: Coffrage (Dallage sol) | C35: LOT 1 | D35: BAT_PRINCIPAL | E35: FONDATIONS | F35: M2 | G35: 66.8 | H35: 46084 | I35: PNR_MEDICAL_CENTER | J35: 5750 | L35: 1 | M35: 0
A36: BPU-ETANCH-TERR-INACC-MONO-063 | B36: Revêtement monocouche sous protection lourde | C36: LOT 2 | D36: BAT_PRINCIPAL | E36: DUPLEX 1 | F36: M2 | G36: 56.75 | H36: 46084 | I36: PNR_MEDICAL_CENTER | J36: 17276 | K36: 4575 | L36: 1 | M36: 1
A37: BPU-ETANCH-TERR-INACC-MONO-063 | B37: Revêtement monocouche sous protection | C37: LOT 2 | D37: BAT_PRINCIPAL | E37: TERRASSE | F37: M2 | G37: 83 | H37: 46084 | I37: PNR_MEDICAL_CENTER | J37: 17276 | K37: 4575 | L37: 1 | M37: 1
A38: BPU-ETANCH-TERR-INACC-MONO-063 | B38: Revêtement bicouche sous protection | C38: LOT 2 | D38: BAT_ANNEXE | E38: TERRASSE | F38: M2 | G38: 231 | H38: 46084 | I38: PNR_MEDICAL_CENTER | J38: 17276 | K38: 4575 | L38: 1 | M38: 1
A39: BPU-MACON-ELEV-DALL-AC-025 | B39: Acier (Dallage sol) | C39: LOT 1 | D39: BAT_PRINCIPAL | E39: FONDATIONS | F39: KG | G39: 2324 | H39: 46084 | I39: PNR_MEDICAL_CENTER | J39: 1380 | L39: 1 | M39: 0
A40: BPU-ETANCH-TERR-INACC-RELEV-064 | B40: Relevé d'étanchéité h=50 cm | C40: LOT 2 | D40: BAT_PRINCIPAL | E40: DUPLEX 1 | F40: ML | G40: 36 | H40: 46084 | I40: PNR_MEDICAL_CENTER | J40: 8641 | K40: 3050 | L40: 1 | M40: 1
...

Sheet RAW_BPU_CHINE
A1: CODE_BPU | B1: DESIGNATION | C1: LOT | D1: UNITE | E1: PU_CHINE_FOB | F1: TYPE_COUT | G1: SOURCE | H1: PROJET_ID | I1: FAM_ARTICLE_ID | J1: PU_IMPORT_NET | K1: DATE_VALIDATION | L1: STATUT
A2: BPU-INSTALL-GEN-MOB-001 | B2: Mobilisation | C2: LOT 1 | D2: Forfait | E2: 4755250 | F2: FORFAIT | G2: PU_CHINE_BPU_LOCAL_01_03 | H2: PNMC_2025 | J2: 4755250 | K2: 46084 | L2: VALIDE
A3: BPU-INSTALL-GEN-BASEVIE-002 | B3: Bureau de chantier, atelier, baraquement et clôture provisoire | C3: LOT 1 | D3: Forfait | E3: 3758730 | F3: FORFAIT | G3: PU_CHINE_BPU_LOCAL_01_03 | H3: PNMC_2025 | J3: 3758730 | K3: 46084 | L3: VALIDE
A4: BPU-INSTALL-GEN-CONC-003 | B4: Abonnement et mensualités concessionnaires | C4: LOT 1 | D4: Forfait | E4: 2507000 | F4: FORFAIT | G4: PU_CHINE_BPU_LOCAL_01_03 | H4: PNMC_2025 | J4: 2507000 | K4: 46084 | L4: VALIDE
A5: BPU-INSTALL-GEN-MAT-004 | B5: Matériel de chantier (engins, manutention) | C5: LOT 1 | D5: Forfait | E5: 4213438 | F5: MATERIAU | G5: PU_CHINE_BPU_LOCAL_01_03 | H5: PNMC_2025 | J5: 4213438 | K5: 46084 | L5: VALIDE
A6: BPU-INSTALL-GEN-DIVERS-005 | B6: Divers (sécurité, ASE, panneau de chantier) | C6: LOT 1 | D6: Forfait | E6: 4945000 | F6: MATERIAU | G6: PU_CHINE_BPU_LOCAL_01_03 | H6: PNMC_2025 | J6: 4945000 | K6: 46084 | L6: VALIDE
A7: BPU-INSTALL-GEN-ETUDE-006 | B7: Études techniques et Essais | C7: LOT 1 | D7: Forfait | E7: 4795500 | F7: MATERIAU | G7: PU_CHINE_BPU_LOCAL_01_03 | H7: PNMC_2025 | J7: 4795500 | K7: 46084 | L7: VALIDE
A8: BPU-INSTALL-GEN-AXE-007 | B8: Ensemble des axes nécessaires / piquetage | C8: LOT 1 | D8: Forfait | E8: 1265000 | F8: FORFAIT | G8: PU_CHINE_BPU_LOCAL_01_03 | H8: PNMC_2025 | J8: 1265000 | K8: 46084 | L8: VALIDE
A9: BPU-DEMO-MUR-ESC-RDC-008 | B9: Démolition murs et escalier (RDC) | C9: LOT 1 | D9: Forfait | E9: 1725000 | F9: MATERIAU | G9: PU_CHINE_BPU_LOCAL_01_03 | H9: PNMC_2025 | J9: 1725000 | K9: 46084 | L9: VALIDE
A10: BPU-DEMO-MUR-ESC-ET1-ANNEXE-009 | B10: Démolition murs, escalier et dalle existante (Bât. Annexe) | C10: LOT 1 | D10: Forfait | E10: 2587500 | F10: MATERIAU | G10: PU_CHINE_BPU_LOCAL_01_03 | H10: PNMC_2025 | J10: 2587500 | K10: 46084 | L10: VALIDE
A11: BPU-DEMO-MUR-ESC-ET2-010 | B11: Démolition murs et escalier (Étage 2) | C11: LOT 1 | D11: Forfait | E11: 1725000 | F11: MATERIAU | G11: PU_CHINE_BPU_LOCAL_01_03 | H11: PNMC_2025 | J11: 1725000 | K11: 46084 | L11: VALIDE
A12: BPU-DEMO-EVAC-GRAVAT-011 | B12: Évacuation des gravats hors site | C12: LOT 1 | D12: Forfait | E12: 552000 | F12: MATERIAU | G12: PU_CHINE_BPU_LOCAL_01_03 | H12: PNMC_2025 | J12: 552000 | K12: 46084 | L12: VALIDE
A13: BPU-MACON-FOND-BET-PROP-013 | B13: Béton de propreté | C13: LOT 1 | D13: m3 | E13: 338720 | F13: MATERIAU | G13: PU_CHINE_BPU_LOCAL_01_03 | H13: PNMC_2025 | J13: 338720 | K13: 46084 | L13: VALIDE
... A101: BPU-PEINT-PLAF-INT-PANTEX-188 | B101: Peinture intérieure plafond (primaire + 2 couches) | C101: LOT 14 | D101: m2 | E101: 6325 | F101: MATERIAU | G101: PU_CHINE_BPU_LOCAL_01_03 | H101: PNMC_2025 | J101: 6325 | K101: 46084 | L101: VALIDE

Sheet ---03_CLEAN---

Sheet CLEAN_METRE
A1: CODE_BPU | B1: DESIGNATION | C1: LOT | D1: BATIMENT_ID | E1: NIVEAU_ID | F1: UNITE | G1: QTE | H1: DATE_MAJ | I1: PROJET_ID
A2: BPU-INSTALL-GEN-MOB-001 | B2: Mobilisation | C2: LOT 1 | D2: BAT_PRINCIPAL | E2: GLOBAL | F2: FORFAIT | G2: 1 | H2: 46084 | I2: PNR_MEDICAL_CENTER
A3: BPU-INSTALL-GEN-BASEVIE-002 | B3: Bureau de chantier, atelier, baraquement et clôture provisoire | C3: LOT 1 | D3: BAT_PRINCIPAL | E3: GLOBAL | F3: FORFAIT | G3: 1 | H3: 46084 | I3: PNR_MEDICAL_CENTER
A4: BPU-INSTALL-GEN-CONC-003 | B4: Abonnement, mensualité concessionnaires | C4: LOT 1 | D4: BAT_PRINCIPAL | E4: GLOBAL | F4: FORFAIT | G4: 1 | H4: 46084 | I4: PNR_MEDICAL_CENTER
A5: BPU-INSTALL-GEN-MAT-004 | B5: Matériel de chantier (engins, manutention etc) | C5: LOT 1 | D5: BAT_PRINCIPAL | E5: GLOBAL | F5: FORFAIT | G5: 1 | H5: 46084 | I5: PNR_MEDICAL_CENTER
A6: BPU-INSTALL-GEN-DIVERS-005 | B6: Divers (sécurité, ASE, panneau de chantier...) | C6: LOT 1 | D6: BAT_PRINCIPAL | E6: GLOBAL | F6: FORFAIT | G6: 1 | H6: 46084 | I6: PNR_MEDICAL_CENTER
A7: BPU-INSTALL-GEN-ETUDE-006 | B7: Études techniques et Essais | C7: LOT 1 | D7: BAT_PRINCIPAL | E7: GLOBAL | F7: FORFAIT | G7: 1 | H7: 46084 | I7: PNR_MEDICAL_CENTER
A8: BPU-INSTALL-GEN-AXE-007 | B8: Ensemble des axes necessaires | C8: LOT 1 | D8: BAT_PRINCIPAL | E8: GLOBAL | F8: FORFAIT | G8: 1 | H8: 46084 | I8: PNR_MEDICAL_CENTER
A9: BPU-DEMO-MUR-ESC-RDC-008 | B9: Démolition des murs et l'escalier (RDC) | C9: LOT 1 | D9: BAT_PRINCIPAL | E9: RDC | F9: FORFAIT | G9: 1 | H9: 46084 | I9: PNR_MEDICAL_CENTER
A10: BPU-DEMO-MUR-ESC-ET1-ANNEXE-009 | B10: Démolition des murs et l'escalier y compris la dalle existente bâtiment annexe (ÉTAGE 1) | C10: LOT 1 | D10: BAT_ANNEXE | E10: ETAGE 1 | F10: FORFAIT | G10: 1 | H10: 46084 | I10: PNR_MEDICAL_CENTER
A11: BPU-DEMO-MUR-ESC-ET2-010 | B11: Démolition des murs et l'escalier (ÉTAGE 2) | C11: LOT 1 | D11: BAT_PRINCIPAL | E11: ETAGE 2 | F11: FORFAIT | G11: 1 | H11: 46084 | I11: PNR_MEDICAL_CENTER
A12: BPU-DEMO-EVAC-GRAVAT-011 | B12: Évacuation des gravats hors site | C12: LOT 1 | D12: BAT_PRINCIPAL | E12: GLOBAL | F12: FORFAIT | G12: 1 | H12: 46084 | I12: PNR_MEDICAL_CENTER
A13: BPU-DEMO-DECAP-CARREAU-012 | B13: Décapage des carreaux sol existants en RDC | C13: LOT 1 | D13: BAT_PRINCIPAL | E13: RDC | F13: M2 | G13: 460 | H13: 46084 | I13: PNR_MEDICAL_CENTER
... A302: BPU-PEINT-PLAF-INT-PANTEX-188 | B302: Peinture intérieure comprissant une impression en pantiprim, 02 couches d'enduits repassés et 02 couches de finitions en pante 800 | C302: LOT 14 | D302: BAT_PRINCIPAL | E302: DUPLEX 1 | F302: M2 | G302: 182 | H302: 46084 | I302: PNR_MEDICAL_CENTER

Sheet DIM_ARTICLE_BPU
A1: CODE_BPU | B1: DESIGNATION | C1: LOT | D1: FAM_ARTICLE_ID | E1: PU_LOCAL | F1: UNITE | G1: PU_CHINE_FOB | H1: PROJET_ID | I1: TYPE_ARTICLE | J1: PU_IMPORT_ESTIME | K1: IMPORTABLE | L1: CATEGORIE_IMPORT | M1: POIDS_KG | N1: VOLUME_M3 | O1: SENSIBILITE_TRANSPORT | P1: SOURCE_PRIX_LOCAL | Q1: SOURCE_PRIX_CHINE | R1: DATE_REFERENCE_PRIX | S1: ACTIF | T1: COMMENTAIRE
A2: BPU-ALUCOBOND-FP-184 | B2: F & P panneau composite de type Alucobond sur toute la façade extérieure | C2: LOT 13 | D2: FA_003 | E2: 174750 | F2: M2 | G2: 9760 | K2: 1 | S2: 1
A3: BPU-ASC-630KG-4ARR-183 | B3: Ascenseur de 630 kg, 4 arrêts, vitesse de 1 m/s etc | C3: LOT 12 | D3: FA_013 | E3: 25300000 | F3: FORFAIT | K3: 1 | S3: 1
A4: BPU-CDA-KIT-PORTE-141 | B4: kit contrôle d'accès porte | C4: LOT 9 | D4: FA_010 | E4: 230000 | F4: FORFAIT | G4: 33550 | K4: 1 | S4: 1
A5: BPU-CLIM-EVAC-COND-115 | B5: Evacuation des condensats | C5: LOT 8 | D5: FA_009 | E5: 1437500 | F5: FORFAIT | K5: 1 | S5: 1
A6: BPU-CLIM-GAINE-SOUF-REPR-116 | B6: Gaine de soufflage et de reprise en laine de verre ou en acier galva ou équivalent y compris toutes sujétions | C6: LOT 8 | D6: FA_009 | E6: 13800000 | F6: FORFAIT | K6: 1 | S6: 1
A7: BPU-CLIM-GRILLE-SOUF-REPR-1000X150-119 | B7: Grille de soufflage et de reprise type LAC 40 (à ailettes inclinées) de France Air ou similaire dimensions 1000x150 mm (pour les débits superieur ou égal à 870 m3/h) avec tous les accessoires de pose suivant plans | C7: LOT 8 | D7: FA_009 | E7: 138000 | F7: FORFAIT | G7: 7930 | K7: 1 | S7: 1
A8: BPU-CLIM-GRILLE-SOUF-REPR-600X150-117 | B8: Grille de soufflage et de reprise type LAC 40 (à ailettes inclinées) de France Air ou similaire dimensions 600x150 mm (pour les débits jusqu'à 660 m3/h) avec tous les accessoires de pose suivant plans | C8: LOT 8 | D8: FA_009 | E8: 80500 | F8: FORFAIT | G8: 4880 | K8: 1 | S8: 1
A9: BPU-CLIM-GRILLE-SOUF-REPR-800X150-118 | B9: Grille de soufflage et de reprise type LAC 40 (à ailettes inclinées) de France Air ou similaire dimensions 800x150 mm (pour les débits comprise entre 660 à 870 m3/h) avec tous les accessoires de pose suivant plans | C9: LOT 8 | D9: FA_009 | E9: 97750 | F9: FORFAIT | G9: 6405 | K9: 1 | S9: 1
A10: BPU-CLIM-KIT-REFNET-111 | B10: Kit de raccordement REFNET de différentes dimensions suivant plans | C10: LOT 8 | D10: FA_009 | E10: 690000 | F10: FORFAIT | K10: 1 | S10: 1
A11: BPU-CLIM-RACC-ELEC-114 | B11: Raccordements électriques et liaisons de communication | C11: LOT 8 | D11: FA_009 | E11: 1265000 | F11: FORFAIT | K11: 1 | S11: 1
A12: BPU-CLIM-RACC-FRIGO-113 | B12: Raccordements frigorifiques y compris toutes sujétions | C12: LOT 8 | D12: FA_009 | E12: 1035000 | F12: FORFAIT | K12: 1 | S12: 1
A13: BPU-CLIM-TELECOM-IR-112 | B13: Télécommande à infrarouge pour les unités intérieures | C13: LOT 8 | D13: FA_009 | E13: 126500 | F13: FORFAIT | G13: 2745 | K13: 1 | S13: 1
A14: BPU-CLIM-VRV-UE-107 | B14: Unité Extérieure Multi-Split Réversible Samsung - Climatisation Multi Split - R32 y compris toutes les sujétions de pose et de raccordement | C14: LOT 8 | D14: FA_009 | E14: 2300000 | F14: FORFAIT | G14: 457500 | K14: 1 | S14: 1
A15: BPU-CLIM-VRV-UI-GAINABLE-1.5CV-108 | B15: Unité intérieure 1.5CV type gainable encastrable de SAMSUNG et toutes sujétions de pose | C15: LOT 8 | D15: FA_009 | E15: 345000 | F15: FORFAIT | G15: 91500 | K15: 1 | S15: 1
A16: BPU-CLIM-VRV-UI-GAINABLE-2CV-109 | B16: Unité intérieure 2CV type gainable encastrable de SAMSUNG et toutes sujétions de pose | C16: LOT 8 | D16: FA_009 | E16: 460000 | F16: FORFAIT | G16: 118950 | K16: 1 | S16: 1
A17: BPU-CLIM-VRV-UI-GAINABLE-3CV-110 | B17: Unité intérieure 3CV type gainable encastrable de SAMSUNG et toutes sujétions de pose | C17: LOT 8 | D17: FA_009 | E17: 575000 | F17: FORFAIT | G17: 152500 | K17: 1 | S17: 1
A18: BPU-DEMO-DECAP-CARREAU-012 | B18: Décapage des carreaux sol existants en RDC | C18: LOT 1 | D18: FA_001 | E18: 5750 | F18: M2 | K18: 1 | S18: 1
A19: BPU-DEMO-EVAC-GRAVAT-011 | B19: Évacuation des gravats hors site | C19: LOT 1 | D19: FA_001 | E19: 552000 | F19: FORFAIT | G19: 552000 | K19: 1 | S19: 1
A20: BPU-DEMO-MUR-ESC-ET1-ANNEXE-009 | B20: Démolition des murs et l'escalier y compris la dalle existente bâtiment annexe (ÉTAGE 1) | C20: LOT 1 | D20: FA_001 | E20: 2587500 | F20: FORFAIT | G20: 2587500 | K20: 1 | S20: 1
A21: BPU-DEMO-MUR-ESC-ET2-010 | B21: Démolition des murs et l'escalier (ÉTAGE 2) | C21: LOT 1 | D21: FA_001 | E21: 1725000 | F21: FORFAIT | G21: 1725000 | K21: 1 | S21: 1
A22: BPU-DEMO-MUR-ESC-RDC-008 | B22: Démolition des murs et l'escalier (RDC) | C22: LOT 1 | D22: FA_001 | E22: 1725000 | F22: FORFAIT | G22: 1725000 | K22: 1 | S22: 1
A23: BPU-ELEC-APPLIQUE-MURALE-088 | B23: Applique mural | C23: LOT 7 | D23: FA_008 | E23: 13800 | F23: FORFAIT | G23: 3355 | K23: 1 | S23: 1
A24: BPU-ELEC-APPLIQUE-MURALE-ETANCHE-089 | B24: Applique mural étanche | C24: LOT 7 | D24: FA_008 | E24: 20700 | F24: FORFAIT | G24: 4880 | K24: 1 | S24: 1
A25: BPU-ELEC-APPLIQUE-SANITAIRE-087 | B25: Applique sanitaire PC+Int | C25: LOT 7 | D25: FA_008 | E25: 10350 | F25: FORFAIT | G25: 2440 | K25: 1 | S25: 1
A26: BPU-ELEC-BAES-AMBIANCE-094 | B26: Bloc autonome d'éclairage de sécurité étanche type à incandescence autonomie 1h de LEGRAND ou similaire : Ambiance | C26: LOT 7 | D26: FA_008 | E26: 67275 | F26: FORFAIT | G26: 14030 | K26: 1 | S26: 1
A27: BPU-ELEC-BAES-DIRECTION-095 | B27: Bloc autonome d'éclairage de sécurité étanche type à incandescence autonomie 1h de LEGRAND ou similaire : Direction | C27: LOT 7 | D27: FA_008 | E27: 43125 | F27: FORFAIT | G27: 9760 | K27: 1 | S27: 1
A28: BPU-ELEC-BP-TEMOIN-098 | B28: Bouton poussoire avec témoin | C28: LOT 7 | D28: FA_008 | E28: 10350 | F28: FORFAIT | G28: 855 | K28: 1 | S28: 1
A29: BPU-ELEC-DALLE-LED-40W-083 | B29: Dalle led 60x60 40W | C29: LOT 7 | D29: FA_008 | E29: 40250 | F29: FORFAIT | G29: 7320 | K29: 1 | S29: 1
A30: BPU-ELEC-DETECT-PRES-099 | B30: Détecteur de presence | C30: LOT 7 | D30: FA_008 | E30: 46000 | F30: FORFAIT | G30: 4270 | K30: 1 | S30: 1
... A46: BPU-ELEC-SPOT-LED-22W-092 | B46: Spot led 22w | C46: LOT 7 | D46: FA_008 | E46: 20700 | F46: FORFAIT | G46: 3050 | K46: 1 | S46: 1
A47: BPU-ETANCH-LOC-RELEV-058 | B47: Relevé d'étanchéité h=50 cm | C47: LOT 2 | D47: FA_002 | E47: 8641 | F47: ML | K47: 1 | S47: 1
A48: BPU-ETANCH-LOC-REV-MONO-057 | B48: Revêtement monocouche | C48: LOT 2 | D48: FA_002 | E48: 17276 | F48: M2 | K48: 1 | S48: 1
A49: BPU-ETANCH-TERR-ACC-BI-060 | B49: Revêtement bicouche sous protection lourde | C49: LOT 2 | D49: FA_002 | E49: 34552 | F49: M2 | G49: 6100 | K49: 1 | S49: 1
A50: BPU-ETANCH-TERR-ACC-FORME-059 | B50: Forme de pente | C50: LOT 2 | D50: FA_002 | E50: 11793 | F50: M2 | G50: 11793 | K50: 1 | S50: 1
A51: BPU-ETANCH-TERR-ACC-RELEV-061 | B51: Relevé d'étanchéité h=50 cm | C51: LOT 2 | D51: FA_002 | E51: 8641 | F51: ML | G51: 3050 | K51: 1 | S51: 1
A52: BPU-ETANCH-TERR-INACC-FORME-062 | B52: Forme de pente | C52: LOT 2 | D52: FA_002 | E52: 11793 | F52: M2 | G52: 11793 | K52: 1 | S52: 1
A53: BPU-ETANCH-TERR-INACC-MONO-063 | B53: Revêtement monocouche sous protection lourde | C53: LOT 2 | D53: FA_002 | E53: 17276 | F53: M2 | G53: 4575 | K53: 1 | S53: 1
A54: BPU-ETANCH-TERR-INACC-RELEV-064 | B54: Relevé d'étanchéité h=50 cm | C54: LOT 2 | D54: FA_002 | E54: 8641 | F54: ML | G54: 3050 | K54: 1 | S54: 1
A55: BPU-FP-CLOISON-BA13-LV-180 | B55: Cloison en BA 13 avec laine de verre | C55: LOT 11 | D55: FA_012 | E55: 39100 | F55: M2 | K55: 1 | S55: 1
...

Sheet CLEAN_BPU_LOCAL
A1: CODE_BPU | B1: DESIGNATION | C1: LOT | D1: UNITE | E1: PU_LOCAL | F1: DATE_REFERENCE | G1: SOURCE | H1: PROJET_ID | I1: TYPE_COUT | J1: ACTIF | K1: FAM_ARTICLE_ID
A2: BPU-INSTALL-GEN-MOB-001 | B2: Mobilisation | C2: LOT 1 | D2: FORFAIT | E2: 4755250 | F2: 45882 | G2: DQE_MEDICAL CENTER_13-08-2025 | H2: PNMC_2025 | I2: MATERIAU | J2: 1 | K2: FA_001
A3: BPU-INSTALL-GEN-BASEVIE-002 | B3: Bureau de chantier, atelier, baraquement et clôture provisoire | C3: LOT 1 | D3: FORFAIT | E3: 3758730 | F3: 45882 | G3: DQE_MEDICAL CENTER_13-08-2025 | H3: PNMC_2025 | I3: MATERIAU | J3: 1 | K3: FA_001
A4: BPU-INSTALL-GEN-CONC-003 | B4: Abonnement, mensualité concessionnaires | C4: LOT 1 | D4: FORFAIT | E4: 2507000 | F4: 45882 | G4: DQE_MEDICAL CENTER_13-08-2025 | H4: PNMC_2025 | I4: MATERIAU | J4: 1 | K4: FA_001
A5: BPU-INSTALL-GEN-MAT-004 | B5: Matériel de chantier (engins, manutention etc) | C5: LOT 1 | D5: FORFAIT | E5: 4213438 | F5: 45882 | G5: DQE_MEDICAL CENTER_13-08-2025 | H5: PNMC_2025 | I5: MATERIAU | J5: 1 | K5: FA_001
A6: BPU-INSTALL-GEN-DIVERS-005 | B6: Divers (sécurité, ASE, panneau de chantier...) | C6: LOT 1 | D6: FORFAIT | E6: 4945000 | F6: 45882 | G6: DQE_MEDICAL CENTER_13-08-2025 | H6: PNMC_2025 | I6: MATERIAU | J6: 1 | K6: FA_001
A7: BPU-INSTALL-GEN-ETUDE-006 | B7: Études techniques et Essais | C7: LOT 1 | D7: FORFAIT | E7: 4795500 | F7: 45882 | G7: DQE_MEDICAL CENTER_13-08-2025 | H7: PNMC_2025 | I7: MATERIAU | J7: 1 | K7: FA_001
A8: BPU-INSTALL-GEN-AXE-007 | B8: Ensemble des axes necessaires | C8: LOT 1 | D8: FORFAIT | E8: 1265000 | F8: 45882 | G8: DQE_MEDICAL CENTER_13-08-2025 | H8: PNMC_2025 | I8: MATERIAU | J8: 1 | K8: FA_001
A9: BPU-DEMO-MUR-ESC-RDC-008 | B9: Démolition des murs et l'escalier (RDC) | C9: LOT 1 | D9: FORFAIT | E9: 1725000 | F9: 45882 | G9: DQE_MEDICAL CENTER_13-08-2025 | H9: PNMC_2025 | I9: MATERIAU | J9: 1 | K9: FA_001
A10: BPU-DEMO-MUR-ESC-ET1-ANNEXE-009 | B10: Démolition des murs et l'escalier y compris la dalle existente bâtiment annexe (ÉTAGE 1) | C10: LOT 1 | D10: FORFAIT | E10: 2587500 | F10: 45882 | G10: DQE_MEDICAL CENTER_13-08-2025 | H10: PNMC_2025 | I10: MATERIAU | J10: 1 | K10: FA_001
A11: BPU-DEMO-MUR-ESC-ET2-010 | B11: Démolition des murs et l'escalier (ÉTAGE 2) | C11: LOT 1 | D11: FORFAIT | E11: 1725000 | F11: 45882 | G11: DQE_MEDICAL CENTER_13-08-2025 | H11: PNMC_2025 | I11: MATERIAU | J11: 1 | K11: FA_001
A12: BPU-DEMO-EVAC-GRAVAT-011 | B12: Évacuation des gravats hors site | C12: LOT 1 | D12: FORFAIT | E12: 552000 | F12: 45882 | G12: DQE_MEDICAL CENTER_13-08-2025 | H12: PNMC_2025 | I12: MATERIAU | J12: 1 | K12: FA_001
A13: BPU-DEMO-DECAP-CARREAU-012 | B13: Décapage des carreaux sol existants en RDC | C13: LOT 1 | D13: M2 | E13: 5750 | F13: 45882 | G13: DQE_MEDICAL CENTER_13-08-2025 | H13: PNMC_2025 | I13: MATERIAU | J13: 1 | K13: FA_001
... A189: BPU-PEINT-PLAF-INT-PANTEX-188 | B189: Peinture intérieure comprissant une impression en pantiprim, 02 couches d'enduits repassés et 02 couches de finitions en pante 800 | C189: LOT 14 | D189: M2 | E189: 6325 | F189: 45882 | G189: DQE_MEDICAL CENTER_13-08-2025 | H189: PNMC_2025 | I189: MATERIAU | J189: 1 | K189: FA_014

Sheet CLEAN_BPU_CHINE
A1: CODE_BPU | B1: DESIGNATION | C1: LOT | D1: UNITE | E1: PU_CHINE_FOB | F1: TYPE_COUT | G1: SOURCE | H1: PROJET_ID | I1: FAM_ARTICLE_ID | J1: PU_IMPORT_NET | K1: DATE_VALIDATION | L1: STATUT
A2: BPU-INSTALL-GEN-MOB-001 | B2: Mobilisation | C2: LOT 1 | D2: FORFAIT | E2: 4755250 | F2: FORFAIT | G2: PU_CHINE_BPU_LOCAL_01_03 | H2: PNMC_2025 | J2: 4755250 | K2: 46084 | L2: VALIDE
A3: BPU-INSTALL-GEN-BASEVIE-002 | B3: Bureau de chantier, atelier, baraquement et clôture provisoire | C3: LOT 1 | D3: FORFAIT | E3: 3758730 | F3: FORFAIT | G3: PU_CHINE_BPU_LOCAL_01_03 | H3: PNMC_2025 | J3: 3758730 | K3: 46084 | L3: VALIDE
